Workbook
Name aa: days+weeks*7
Name asadasd: aa+[0]!firstdate-WEEKDAY([0]!firstdate)-weekday_option
Name assigntype: #REF!
Name calendar: 'Request New User Hybrid'!daygrid+'Request New User Hybrid'!firstdate-WEEKDAY('Request New User Hybrid'!firstdate)-'Request New User Hybrid'!weekday_option
Name calendar: daygrid+[0]!firstdate-WEEKDAY([0]!firstdate)-weekday_option
Name channel: #REF!
Name daygrid: 'Request New User Hybrid'!days+'Request New User Hybrid'!weeks*7
Name daygrid: days+weeks*7
Name daypattern: {1,1,2,2,3,3,4,4,5,5,6,6,7}
Name daypattern: {1,1,2,2,3,3,4,4,5,5,6,6,7}
Name days: {0,1,2,3,4,5,6}
Name days: {0,1,2,3,4,5,6}
Name DayToStart: #REF!
Name Display_Week: #REF!
Name firstdate: DATE([0]!YearToDisplay,'Request New User Hybrid'!month,1)
Name firstdate: DATE([0]!YearToDisplay,[0]!month,1)
Name month: MATCH([0]!MonthToDisplay,'Request New User Hybrid'!months,0)
Name month: MATCH([0]!MonthToDisplay,months,0)
Name months: {"January","February","March","April","May","June","July","August","September","October","November","December"}
Name months: {"January","February","March","April","May","June","July","August","September","October","November","December"}
Name MonthToDisplay: #REF!
Name MonthToDisplayNumber: MATCH([0]!MonthToDisplay,'Request New User Hybrid'!months,0)
Name MonthToDisplayNumber: MATCH([0]!MonthToDisplay,months,0)
Name nasional: #REF!
Name position: #REF!
Name prefnotchnl: #REF!
Name Project_Start: #REF!
Name roles: #REF!
Name weekday_option: MATCH([0]!DayToStart,'Request New User Hybrid'!weekdays_reversed,0)-2
Name weekday_option: MATCH(DayToStart,weekdays_reversed,0)-2
Name weekdays: {"Monday","Tuesday","Wednesday","Thursday","Friday","Saturday","Sunday"}
Name weekdays: {"Monday","Tuesday","Wednesday","Thursday","Friday","Saturday","Sunday"}
Name weekdays_reversed: {"Sunday","Saturday","Friday","Thursday","Wednesday","Tuesday","Monday"}
Name weekdays_reversed: {"Sunday","Saturday","Friday","Thursday","Wednesday","Tuesday","Monday"}
Name weeks: {0;1;2;3;4;5;6}
Name weeks: {0;1;2;3;4;5;6}
Name YearToDisplay: #REF!
Name yorn: #REF!

Sheet Request New User Hybrid
A3: DSE MOVEMENT TEMPLATE
A4: BRAND (IM3/3ID) | B4: REGION | C4: BRANCH | D4: MICRO CLUSTER | E4: PARTNER TERRITORY | F4: MPX Im3 | G4: MPX 3ID | H4: ID DSE Im3 | I4: ID DSE 3ID | J4: AGENCY NAME | K4: NAMA DSE | L4: ALAMAT | M4: NO KTP | N4: JENIS KELAMIN | O4: ROLE (SPV/CSO) | P4: MSISDN (YG DIDAFTARKAN MOBO) | Q4: EMAIL | R4: REMARKS | S4: RAYON
A5: IOH | B5: INNER JAKARTA | C5: WEST JAKARTA | D5: CS CENGKARENG | E5: PT-CENGKARENG | F5: SDP22310006 | G5: KSK52606209 | H5: DSETTE1 | I5: =H5&"3ID" -> DSETTE13ID | J5: PERMATA | K5: Rizki Ramdhani | L5: JL MANGGIS NO 36 RT.003/RW.005 KOTA JAKARTA BARAT 11630 | M5: 3.1730825e+15 | N5: LAKI-LAKI | O5: CSO | P5: 62895396012060 | Q5: kiki290391@gmail.com | R5: DONE
H6: DSE123 | I6: =H6&"3ID" -> DSE1233ID | K6: Indra
H7: CSO-SDEW | I7: 1-23423423
H8: DSE-DSNH | I8: 234234234
H9: 234234234 | I9: 2342342343ID
A10: BRAND (IM3/3ID) | B10: REGION | C10: BRANCH | D10: MICRO CLUSTER | E10: PARTNER TERRITORY | F10: MPX Im3 | G10: MPX 3ID | H10: ID DSE Im3 | I10: ID DSE 3ID | J10: AGENCY NAME | K10: NAMA DSE | L10: ALAMAT | M10: NO KTP | N10: JENIS KELAMIN | O10: ROLE (SPV/CSO) | P10: MSISDN (YG DIDAFTARKAN MOBO) | Q10: EMAIL | R10: REMARKS | S10: RAYON
A11: =A10=A4 -> TRUE | B11: =B10=B4 -> TRUE | C11: =C10=C4 -> TRUE | D11: =D10=D4 -> TRUE | E11: =E10=E4 -> TRUE | F11: =F10=F4 -> TRUE | G11: =G10=G4 -> TRUE | H11: =H10=H4 -> TRUE | ... S11: =S10=S4 -> TRUE
A13: BRAND (IM3/3ID) | B13: REGION | C13: BRANCH | D13: MICRO CLUSTER | E13: PARTNER TERRITORY | F13: MPX Im3 | G13: MPX 3ID | H13: ID DSE Im3 | I13: ID DSE 3ID | J13: AGENCY NAME | K13: NAMA DSE | L13: ALAMAT | M13: NO KTP | N13: JENIS KELAMIN | O13: ROLE (SPV/CSO) | P13: MSISDN (YG DIDAFTARKAN MOBO) | Q13: EMAIL | R13: REMARKS | S13: Rayon
A14: =A13=A4 -> TRUE | B14: =B13=B4 -> TRUE | C14: =C13=C4 -> TRUE | D14: =D13=D4 -> TRUE | E14: =E13=E4 -> TRUE | F14: =F13=F4 -> TRUE | G14: =G13=G4 -> TRUE | H14: =H13=H4 -> TRUE | ... S14: =S13=S4 -> TRUE
A16: BRAND (IM3/3ID) | B16: REGION | C16: BRANCH | D16: MICRO CLUSTER | E16: PARTNER TERRITORY | F16: MPX Im3 | G16: MPX 3ID | H16: ID DSE Im3 | I16: ID DSE 3ID | J16: AGENCY NAME | K16: NAMA DSE | L16: ALAMAT | M16: NO KTP | N16: JENIS KELAMIN | O16: ROLE (SPV/CSO) | P16: MSISDN (YG DIDAFTARKAN MOBO) | Q16: EMAIL | R16: REMARKS | S16: RAYON
A17: =A16=A4 -> TRUE | B17: =B16=B4 -> TRUE | C17: =C16=C4 -> TRUE | D17: =D16=D4 -> TRUE | E17: =E16=E4 -> TRUE | F17: =F16=F4 -> TRUE | G17: =G16=G4 -> TRUE | H17: =H16=H4 -> TRUE | ... S17: =S16=S4 -> TRUE

Sheet SUMMARY
F1: IM3 | K1: 3ID
C2: BRANCH | D2: #DSE | E2: x | F2: ACTIVE | G2: PENDING ACTIVE | H2: CLOSED | I2: NOT FOUND | J2: x | K2: ACTIVE | L2: PENDING ACTIVE | M2: ACTIVE | RE-PARENTING | N2: NOT FOUND
C3: BEKASI | D3: =SUMIFS(D$13:D$52,$A$13:$A$52,$C3) -> 34 | F3: =SUMIFS(F$13:F$52,$A$13:$A$52,$C3) -> 32 | G3: =SUMIFS(G$13:G$52,$A$13:$A$52,$C3) -> 1 | H3: =SUMIFS(H$13:H$52,$A$13:$A$52,$C3) -> 1 | I3: =SUMIFS(I$13:I$52,$A$13:$A$52,$C3) -> 0 | K3: =SUMIFS(K$13:K$52,$A$13:$A$52,$C3) -> 30 | L3: =SUMIFS(L$13:L$52,$A$13:$A$52,$C3) -> 3 | M3: =SUMIFS(M$13:M$52,$A$13:$A$52,$C3) -> 1 | N3: =SUMIFS(N$13:N$52,$A$13:$A$52,$C3) -> 0
C4: CENTRAL NORTH JAKARTA | D4: =SUMIFS(D$13:D$52,$A$13:$A$52,$C4) -> 37 | F4: =SUMIFS(F$13:F$52,$A$13:$A$52,$C4) -> 37 | G4: =SUMIFS(G$13:G$52,$A$13:$A$52,$C4) -> 0 | H4: =SUMIFS(H$13:H$52,$A$13:$A$52,$C4) -> 0 | I4: =SUMIFS(I$13:I$52,$A$13:$A$52,$C4) -> 0 | K4: =SUMIFS(K$13:K$52,$A$13:$A$52,$C4) -> 25 | L4: =SUMIFS(L$13:L$52,$A$13:$A$52,$C4) -> 5 | M4: =SUMIFS(M$13:M$52,$A$13:$A$52,$C4) -> 1 | N4: =SUMIFS(N$13:N$52,$A$13:$A$52,$C4) -> 6
C5: SOUTH JAKARTA DEPOK | D5: =SUMIFS(D$13:D$52,$A$13:$A$52,$C5) -> 55 | F5: =SUMIFS(F$13:F$52,$A$13:$A$52,$C5) -> 51 | G5: =SUMIFS(G$13:G$52,$A$13:$A$52,$C5) -> 2 | H5: =SUMIFS(H$13:H$52,$A$13:$A$52,$C5) -> 1 | I5: =SUMIFS(I$13:I$52,$A$13:$A$52,$C5) -> 1 | K5: =SUMIFS(K$13:K$52,$A$13:$A$52,$C5) -> 46 | L5: =SUMIFS(L$13:L$52,$A$13:$A$52,$C5) -> 6 | M5: =SUMIFS(M$13:M$52,$A$13:$A$52,$C5) -> 3 | N5: =SUMIFS(N$13:N$52,$A$13:$A$52,$C5) -> 0
C6: EAST JAKARTA | D6: =SUMIFS(D$13:D$52,$A$13:$A$52,$C6) -> 36 | F6: =SUMIFS(F$13:F$52,$A$13:$A$52,$C6) -> 34 | G6: =SUMIFS(G$13:G$52,$A$13:$A$52,$C6) -> 1 | H6: =SUMIFS(H$13:H$52,$A$13:$A$52,$C6) -> 0 | I6: =SUMIFS(I$13:I$52,$A$13:$A$52,$C6) -> 1 | K6: =SUMIFS(K$13:K$52,$A$13:$A$52,$C6) -> 29 | L6: =SUMIFS(L$13:L$52,$A$13:$A$52,$C6) -> 6 | M6: =SUMIFS(M$13:M$52,$A$13:$A$52,$C6) -> 0 | N6: =SUMIFS(N$13:N$52,$A$13:$A$52,$C6) -> 1
C7: KAB BEKASI | D7: =SUMIFS(D$13:D$52,$A$13:$A$52,$C7) -> 41 | F7: =SUMIFS(F$13:F$52,$A$13:$A$52,$C7) -> 39 | G7: =SUMIFS(G$13:G$52,$A$13:$A$52,$C7) -> 0 | H7: =SUMIFS(H$13:H$52,$A$13:$A$52,$C7) -> 2 | I7: =SUMIFS(I$13:I$52,$A$13:$A$52,$C7) -> 0 | K7: =SUMIFS(K$13:K$52,$A$13:$A$52,$C7) -> 36 | L7: =SUMIFS(L$13:L$52,$A$13:$A$52,$C7) -> 5 | M7: =SUMIFS(M$13:M$52,$A$13:$A$52,$C7) -> 0 | N7: =SUMIFS(N$13:N$52,$A$13:$A$52,$C7) -> 0
C8: KARAWANG | D8: =SUMIFS(D$13:D$52,$A$13:$A$52,$C8) -> 44 | F8: =SUMIFS(F$13:F$52,$A$13:$A$52,$C8) -> 43 | G8: =SUMIFS(G$13:G$52,$A$13:$A$52,$C8) -> 1 | H8: =SUMIFS(H$13:H$52,$A$13:$A$52,$C8) -> 0 | I8: =SUMIFS(I$13:I$52,$A$13:$A$52,$C8) -> 0 | K8: =SUMIFS(K$13:K$52,$A$13:$A$52,$C8) -> 38 | L8: =SUMIFS(L$13:L$52,$A$13:$A$52,$C8) -> 4 | M8: =SUMIFS(M$13:M$52,$A$13:$A$52,$C8) -> 1 | N8: =SUMIFS(N$13:N$52,$A$13:$A$52,$C8) -> 1
C9: WEST JAKARTA | D9: =SUMIFS(D$13:D$52,$A$13:$A$52,$C9) -> 25 | F9: =SUMIFS(F$13:F$52,$A$13:$A$52,$C9) -> 25 | G9: =SUMIFS(G$13:G$52,$A$13:$A$52,$C9) -> 0 | H9: =SUMIFS(H$13:H$52,$A$13:$A$52,$C9) -> 0 | I9: =SUMIFS(I$13:I$52,$A$13:$A$52,$C9) -> 0 | K9: =SUMIFS(K$13:K$52,$A$13:$A$52,$C9) -> 19 | L9: =SUMIFS(L$13:L$52,$A$13:$A$52,$C9) -> 6 | M9: =SUMIFS(M$13:M$52,$A$13:$A$52,$C9) -> 0 | N9: =SUMIFS(N$13:N$52,$A$13:$A$52,$C9) -> 0
D10: =SUM(D3:D9) -> 272 | F10: =SUM(F3:F9) -> 261 | G10: =SUM(G3:G9) -> 5 | H10: =SUM(H3:H9) -> 4 | I10: =SUM(I3:I9) -> 2 | K10: =SUM(K3:K9) -> 223 | L10: =SUM(L3:L9) -> 35 | M10: =SUM(M3:M9) -> 6 | N10: =SUM(N3:N9) -> 8
F12: IM3 | K12: 3ID
A13: BRANCH | B13: MICRO CLUSTER | C13: PARTNER TERRITORY | D13: #DSE | E13: x | F13: ACTIVE | G13: PENDING ACTIVE | H13: CLOSED | I13: NOT FOUND | J13: x | K13: ACTIVE | L13: PENDING ACTIVE | M13: ACTIVE | RE-PARENTING | N13: NOT FOUND
A14: BEKASI | B14: MC-BEKASI TENGAH | C14: PT-BEKASI TENGAH | D14: =COUNTIFS('MASTER DSE OCT Inn'!E:E,SUMMARY!C14) -> 10 | F14: =COUNTIFS('MASTER DSE OCT Inn'!$Z:$Z,F$13,'MASTER DSE OCT Inn'!$E:$E,SUMMARY!$C14) -> 9 | G14: =COUNTIFS('MASTER DSE OCT Inn'!$Z:$Z,G$13,'MASTER DSE OCT Inn'!$E:$E,SUMMARY!$C14) -> 1 | H14: =COUNTIFS('MASTER DSE OCT Inn'!$Z:$Z,H$13,'MASTER DSE OCT Inn'!$E:$E,SUMMARY!$C14) -> 0 | I14: =COUNTIFS('MASTER DSE OCT Inn'!$Z:$Z,I$13,'MASTER DSE OCT Inn'!$E:$E,SUMMARY!$C14) -> 0 | K14: =COUNTIFS('MASTER DSE OCT Inn'!$AA:$AA,K$13,'MASTER DSE OCT Inn'!$E:$E,SUMMARY!$C14) -> 8 | L14: =COUNTIFS('MASTER DSE OCT Inn'!$AA:$AA,L$13,'MASTER DSE OCT Inn'!$E:$E,SUMMARY!$C14) -> 1 | M14: =COUNTIFS('MASTER DSE OCT Inn'!$AA:$AA,M$13,'MASTER DSE OCT Inn'!$E:$E,SUMMARY!$C14) -> 1 | N14: =COUNTIFS('MASTER DSE OCT Inn'!$AA:$AA,N$13,'MASTER DSE OCT Inn'!$E:$E,SUMMARY!$C14) -> 0
A15: BEKASI | B15: MC-BEKASI UTARA | C15: PT-BEKASI UTARA | D15: =COUNTIFS('MASTER DSE OCT Inn'!E:E,SUMMARY!C15) -> 6 | F15: =COUNTIFS('MASTER DSE OCT Inn'!$Z:$Z,F$13,'MASTER DSE OCT Inn'!$E:$E,SUMMARY!$C15) -> 6 | G15: =COUNTIFS('MASTER DSE OCT Inn'!$Z:$Z,G$13,'MASTER DSE OCT Inn'!$E:$E,SUMMARY!$C15) -> 0 | H15: =COUNTIFS('MASTER DSE OCT Inn'!$Z:$Z,H$13,'MASTER DSE OCT Inn'!$E:$E,SUMMARY!$C15) -> 0 | I15: =COUNTIFS('MASTER DSE OCT Inn'!$Z:$Z,I$13,'MASTER DSE OCT Inn'!$E:$E,SUMMARY!$C15) -> 0 | K15: =COUNTIFS('MASTER DSE OCT Inn'!$AA:$AA,K$13,'MASTER DSE OCT Inn'!$E:$E,SUMMARY!$C15) -> 6 | L15: =COUNTIFS('MASTER DSE OCT Inn'!$AA:$AA,L$13,'MASTER DSE OCT Inn'!$E:$E,SUMMARY!$C15) -> 0 | M15: =COUNTIFS('MASTER DSE OCT Inn'!$AA:$AA,M$13,'MASTER DSE OCT Inn'!$E:$E,SUMMARY!$C15) -> 0 | N15: =COUNTIFS('MASTER DSE OCT Inn'!$AA:$AA,N$13,'MASTER DSE OCT Inn'!$E:$E,SUMMARY!$C15) -> 0
A16: BEKASI | B16: MC-MUSTIKA JAYA | C16: PT-MUSTIKA JAYA | D16: =COUNTIFS('MASTER DSE OCT Inn'!E:E,SUMMARY!C16) -> 8 | F16: =COUNTIFS('MASTER DSE OCT Inn'!$Z:$Z,F$13,'MASTER DSE OCT Inn'!$E:$E,SUMMARY!$C16) -> 7 | G16: =COUNTIFS('MASTER DSE OCT Inn'!$Z:$Z,G$13,'MASTER DSE OCT Inn'!$E:$E,SUMMARY!$C16) -> 0 | H16: =COUNTIFS('MASTER DSE OCT Inn'!$Z:$Z,H$13,'MASTER DSE OCT Inn'!$E:$E,SUMMARY!$C16) -> 1 | I16: =COUNTIFS('MASTER DSE OCT Inn'!$Z:$Z,I$13,'MASTER DSE OCT Inn'!$E:$E,SUMMARY!$C16) -> 0 | K16: =COUNTIFS('MASTER DSE OCT Inn'!$AA:$AA,K$13,'MASTER DSE OCT Inn'!$E:$E,SUMMARY!$C16) -> 6 | L16: =COUNTIFS('MASTER DSE OCT Inn'!$AA:$AA,L$13,'MASTER DSE OCT Inn'!$E:$E,SUMMARY!$C16) -> 2 | M16: =COUNTIFS('MASTER DSE OCT Inn'!$AA:$AA,M$13,'MASTER DSE OCT Inn'!$E:$E,SUMMARY!$C16) -> 0 | N16: =COUNTIFS('MASTER DSE OCT Inn'!$AA:$AA,N$13,'MASTER DSE OCT Inn'!$E:$E,SUMMARY!$C16) -> 0
A17: BEKASI | B17: MC-PONDOK GEDE | C17: PT-PONDOK GEDE | D17: =COUNTIFS('MASTER DSE OCT Inn'!E:E,SUMMARY!C17) -> 10 | F17: =COUNTIFS('MASTER DSE OCT Inn'!$Z:$Z,F$13,'MASTER DSE OCT Inn'!$E:$E,SUMMARY!$C17) -> 10 | G17: =COUNTIFS('MASTER DSE OCT Inn'!$Z:$Z,G$13,'MASTER DSE OCT Inn'!$E:$E,SUMMARY!$C17) -> 0 | H17: =COUNTIFS('MASTER DSE OCT Inn'!$Z:$Z,H$13,'MASTER DSE OCT Inn'!$E:$E,SUMMARY!$C17) -> 0 | I17: =COUNTIFS('MASTER DSE OCT Inn'!$Z:$Z,I$13,'MASTER DSE OCT Inn'!$E:$E,SUMMARY!$C17) -> 0 | K17: =COUNTIFS('MASTER DSE OCT Inn'!$AA:$AA,K$13,'MASTER DSE OCT Inn'!$E:$E,SUMMARY!$C17) -> 10 | L17: =COUNTIFS('MASTER DSE OCT Inn'!$AA:$AA,L$13,'MASTER DSE OCT Inn'!$E:$E,SUMMARY!$C17) -> 0 | M17: =COUNTIFS('MASTER DSE OCT Inn'!$AA:$AA,M$13,'MASTER DSE OCT Inn'!$E:$E,SUMMARY!$C17) -> 0 | N17: =COUNTIFS('MASTER DSE OCT Inn'!$AA:$AA,N$13,'MASTER DSE OCT Inn'!$E:$E,SUMMARY!$C17) -> 0
A18: CENTRAL NORTH JAKARTA | B18: MC-CEMPAKA PUTIH | C18: PT-CEMPAKA PUTIH | D18: =COUNTIFS('MASTER DSE OCT Inn'!E:E,SUMMARY!C18) -> 9 | F18: =COUNTIFS('MASTER DSE OCT Inn'!$Z:$Z,F$13,'MASTER DSE OCT Inn'!$E:$E,SUMMARY!$C18) -> 9 | G18: =COUNTIFS('MASTER DSE OCT Inn'!$Z:$Z,G$13,'MASTER DSE OCT Inn'!$E:$E,SUMMARY!$C18) -> 0 | H18: =COUNTIFS('MASTER DSE OCT Inn'!$Z:$Z,H$13,'MASTER DSE OCT Inn'!$E:$E,SUMMARY!$C18) -> 0 | I18: =COUNTIFS('MASTER DSE OCT Inn'!$Z:$Z,I$13,'MASTER DSE OCT Inn'!$E:$E,SUMMARY!$C18) -> 0 | K18: =COUNTIFS('MASTER DSE OCT Inn'!$AA:$AA,K$13,'MASTER DSE OCT Inn'!$E:$E,SUMMARY!$C18) -> 8 | L18: =COUNTIFS('MASTER DSE OCT Inn'!$AA:$AA,L$13,'MASTER DSE OCT Inn'!$E:$E,SUMMARY!$C18) -> 0 | M18: =COUNTIFS('MASTER DSE OCT Inn'!$AA:$AA,M$13,'MASTER DSE OCT Inn'!$E:$E,SUMMARY!$C18) -> 1 | N18: =COUNTIFS('MASTER DSE OCT Inn'!$AA:$AA,N$13,'MASTER DSE OCT Inn'!$E:$E,SUMMARY!$C18) -> 0
A19: CENTRAL NORTH JAKARTA | B19: MC-KELAPA GADING | C19: PT-KELAPA GADING | D19: =COUNTIFS('MASTER DSE OCT Inn'!E:E,SUMMARY!C19) -> 7 | F19: =COUNTIFS('MASTER DSE OCT Inn'!$Z:$Z,F$13,'MASTER DSE OCT Inn'!$E:$E,SUMMARY!$C19) -> 7 | G19: =COUNTIFS('MASTER DSE OCT Inn'!$Z:$Z,G$13,'MASTER DSE OCT Inn'!$E:$E,SUMMARY!$C19) -> 0 | H19: =COUNTIFS('MASTER DSE OCT Inn'!$Z:$Z,H$13,'MASTER DSE OCT Inn'!$E:$E,SUMMARY!$C19) -> 0 | I19: =COUNTIFS('MASTER DSE OCT Inn'!$Z:$Z,I$13,'MASTER DSE OCT Inn'!$E:$E,SUMMARY!$C19) -> 0 | K19: =COUNTIFS('MASTER DSE OCT Inn'!$AA:$AA,K$13,'MASTER DSE OCT Inn'!$E:$E,SUMMARY!$C19) -> 7 | L19: =COUNTIFS('MASTER DSE OCT Inn'!$AA:$AA,L$13,'MASTER DSE OCT Inn'!$E:$E,SUMMARY!$C19) -> 0 | M19: =COUNTIFS('MASTER DSE OCT Inn'!$AA:$AA,M$13,'MASTER DSE OCT Inn'!$E:$E,SUMMARY!$C19) -> 0 | N19: =COUNTIFS('MASTER DSE OCT Inn'!$AA:$AA,N$13,'MASTER DSE OCT Inn'!$E:$E,SUMMARY!$C19) -> 0
A20: CENTRAL NORTH JAKARTA | B20: MC-PADEMANGAN | C20: PT-PADEMANGAN | D20: =COUNTIFS('MASTER DSE OCT Inn'!E:E,SUMMARY!C20) -> 8 | F20: =COUNTIFS('MASTER DSE OCT Inn'!$Z:$Z,F$13,'MASTER DSE OCT Inn'!$E:$E,SUMMARY!$C20) -> 8 | G20: =COUNTIFS('MASTER DSE OCT Inn'!$Z:$Z,G$13,'MASTER DSE OCT Inn'!$E:$E,SUMMARY!$C20) -> 0 | H20: =COUNTIFS('MASTER DSE OCT Inn'!$Z:$Z,H$13,'MASTER DSE OCT Inn'!$E:$E,SUMMARY!$C20) -> 0 | I20: =COUNTIFS('MASTER DSE OCT Inn'!$Z:$Z,I$13,'MASTER DSE OCT Inn'!$E:$E,SUMMARY!$C20) -> 0 | K20: =COUNTIFS('MASTER DSE OCT Inn'!$AA:$AA,K$13,'MASTER DSE OCT Inn'!$E:$E,SUMMARY!$C20) -> 1 | L20: =COUNTIFS('MASTER DSE OCT Inn'!$AA:$AA,L$13,'MASTER DSE OCT Inn'!$E:$E,SUMMARY!$C20) -> 2 | M20: =COUNTIFS('MASTER DSE OCT Inn'!$AA:$AA,M$13,'MASTER DSE OCT Inn'!$E:$E,SUMMARY!$C20) -> 0 | N20: =COUNTIFS('MASTER DSE OCT Inn'!$AA:$AA,N$13,'MASTER DSE OCT Inn'!$E:$E,SUMMARY!$C20) -> 5
A21: CENTRAL NORTH JAKARTA | B21: MC-TANAH ABANG | C21: PT-TANAH ABANG | D21: =COUNTIFS('MASTER DSE OCT Inn'!E:E,SUMMARY!C21) -> 5 | F21: =COUNTIFS('MASTER DSE OCT Inn'!$Z:$Z,F$13,'MASTER DSE OCT Inn'!$E:$E,SUMMARY!$C21) -> 5 | G21: =COUNTIFS('MASTER DSE OCT Inn'!$Z:$Z,G$13,'MASTER DSE OCT Inn'!$E:$E,SUMMARY!$C21) -> 0 | H21: =COUNTIFS('MASTER DSE OCT Inn'!$Z:$Z,H$13,'MASTER DSE OCT Inn'!$E:$E,SUMMARY!$C21) -> 0 | I21: =COUNTIFS('MASTER DSE OCT Inn'!$Z:$Z,I$13,'MASTER DSE OCT Inn'!$E:$E,SUMMARY!$C21) -> 0 | K21: =COUNTIFS('MASTER DSE OCT Inn'!$AA:$AA,K$13,'MASTER DSE OCT Inn'!$E:$E,SUMMARY!$C21) -> 5 | L21: =COUNTIFS('MASTER DSE OCT Inn'!$AA:$AA,L$13,'MASTER DSE OCT Inn'!$E:$E,SUMMARY!$C21) -> 0 | M21: =COUNTIFS('MASTER DSE OCT Inn'!$AA:$AA,M$13,'MASTER DSE OCT Inn'!$E:$E,SUMMARY!$C21) -> 0 | N21: =COUNTIFS('MASTER DSE OCT Inn'!$AA:$AA,N$13,'MASTER DSE OCT Inn'!$E:$E,SUMMARY!$C21) -> 0
A22: CENTRAL NORTH JAKARTA | B22: MC-TANJUNG PRIOK | C22: PT-TANJUNG PRIOK | D22: =COUNTIFS('MASTER DSE OCT Inn'!E:E,SUMMARY!C22) -> 8 | F22: =COUNTIFS('MASTER DSE OCT Inn'!$Z:$Z,F$13,'MASTER DSE OCT Inn'!$E:$E,SUMMARY!$C22) -> 8 | G22: =COUNTIFS('MASTER DSE OCT Inn'!$Z:$Z,G$13,'MASTER DSE OCT Inn'!$E:$E,SUMMARY!$C22) -> 0 | H22: =COUNTIFS('MASTER DSE OCT Inn'!$Z:$Z,H$13,'MASTER DSE OCT Inn'!$E:$E,SUMMARY!$C22) -> 0 | I22: =COUNTIFS('MASTER DSE OCT Inn'!$Z:$Z,I$13,'MASTER DSE OCT Inn'!$E:$E,SUMMARY!$C22) -> 0 | K22: =COUNTIFS('MASTER DSE OCT Inn'!$AA:$AA,K$13,'MASTER DSE OCT Inn'!$E:$E,SUMMARY!$C22) -> 4 | L22: =COUNTIFS('MASTER DSE OCT Inn'!$AA:$AA,L$13,'MASTER DSE OCT Inn'!$E:$E,SUMMARY!$C22) -> 3 | M22: =COUNTIFS('MASTER DSE OCT Inn'!$AA:$AA,M$13,'MASTER DSE OCT Inn'!$E:$E,SUMMARY!$C22) -> 0 | N22: =COUNTIFS('MASTER DSE OCT Inn'!$AA:$AA,N$13,'MASTER DSE OCT Inn'!$E:$E,SUMMARY!$C22) -> 1
A23: SOUTH JAKARTA DEPOK | B23: MC-BEJI | C23: PT-BEJI | D23: =COUNTIFS('MASTER DSE OCT Inn'!E:E,SUMMARY!C23) -> 6 | F23: =COUNTIFS('MASTER DSE OCT Inn'!$Z:$Z,F$13,'MASTER DSE OCT Inn'!$E:$E,SUMMARY!$C23) -> 5 | G23: =COUNTIFS('MASTER DSE OCT Inn'!$Z:$Z,G$13,'MASTER DSE OCT Inn'!$E:$E,SUMMARY!$C23) -> 0 | H23: =COUNTIFS('MASTER DSE OCT Inn'!$Z:$Z,H$13,'MASTER DSE OCT Inn'!$E:$E,SUMMARY!$C23) -> 0 | I23: =COUNTIFS('MASTER DSE OCT Inn'!$Z:$Z,I$13,'MASTER DSE OCT Inn'!$E:$E,SUMMARY!$C23) -> 1 | K23: =COUNTIFS('MASTER DSE OCT Inn'!$AA:$AA,K$13,'MASTER DSE OCT Inn'!$E:$E,SUMMARY!$C23) -> 3 | L23: =COUNTIFS('MASTER DSE OCT Inn'!$AA:$AA,L$13,'MASTER DSE OCT Inn'!$E:$E,SUMMARY!$C23) -> 0 | M23: =COUNTIFS('MASTER DSE OCT Inn'!$AA:$AA,M$13,'MASTER DSE OCT Inn'!$E:$E,SUMMARY!$C23) -> 3 | N23: =COUNTIFS('MASTER DSE OCT Inn'!$AA:$AA,N$13,'MASTER DSE OCT Inn'!$E:$E,SUMMARY!$C23) -> 0
A24: SOUTH JAKARTA DEPOK | B24: MC-CIMANGGIS | C24: PT-CIMANGGIS | D24: =COUNTIFS('MASTER DSE OCT Inn'!E:E,SUMMARY!C24) -> 6 | F24: =COUNTIFS('MASTER DSE OCT Inn'!$Z:$Z,F$13,'MASTER DSE OCT Inn'!$E:$E,SUMMARY!$C24) -> 5 | G24: =COUNTIFS('MASTER DSE OCT Inn'!$Z:$Z,G$13,'MASTER DSE OCT Inn'!$E:$E,SUMMARY!$C24) -> 1 | H24: =COUNTIFS('MASTER DSE OCT Inn'!$Z:$Z,H$13,'MASTER DSE OCT Inn'!$E:$E,SUMMARY!$C24) -> 0 | I24: =COUNTIFS('MASTER DSE OCT Inn'!$Z:$Z,I$13,'MASTER DSE OCT Inn'!$E:$E,SUMMARY!$C24) -> 0 | K24: =COUNTIFS('MASTER DSE OCT Inn'!$AA:$AA,K$13,'MASTER DSE OCT Inn'!$E:$E,SUMMARY!$C24) -> 6 | L24: =COUNTIFS('MASTER DSE OCT Inn'!$AA:$AA,L$13,'MASTER DSE OCT Inn'!$E:$E,SUMMARY!$C24) -> 0 | M24: =COUNTIFS('MASTER DSE OCT Inn'!$AA:$AA,M$13,'MASTER DSE OCT Inn'!$E:$E,SUMMARY!$C24) -> 0 | N24: =COUNTIFS('MASTER DSE OCT Inn'!$AA:$AA,N$13,'MASTER DSE OCT Inn'!$E:$E,SUMMARY!$C24) -> 0
A25: SOUTH JAKARTA DEPOK | B25: MC-CIPAYUNG | C25: PT-CIPAYUNG | D25: =COUNTIFS('MASTER DSE OCT Inn'!E:E,SUMMARY!C25) -> 8 | F25: =COUNTIFS('MASTER DSE OCT Inn'!$Z:$Z,F$13,'MASTER DSE OCT Inn'!$E:$E,SUMMARY!$C25) -> 8 | G25: =COUNTIFS('MASTER DSE OCT Inn'!$Z:$Z,G$13,'MASTER DSE OCT Inn'!$E:$E,SUMMARY!$C25) -> 0 | H25: =COUNTIFS('MASTER DSE OCT Inn'!$Z:$Z,H$13,'MASTER DSE OCT Inn'!$E:$E,SUMMARY!$C25) -> 0 | I25: =COUNTIFS('MASTER DSE OCT Inn'!$Z:$Z,I$13,'MASTER DSE OCT Inn'!$E:$E,SUMMARY!$C25) -> 0 | K25: =COUNTIFS('MASTER DSE OCT Inn'!$AA:$AA,K$13,'MASTER DSE OCT Inn'!$E:$E,SUMMARY!$C25) -> 8 | L25: =COUNTIFS('MASTER DSE OCT Inn'!$AA:$AA,L$13,'MASTER DSE OCT Inn'!$E:$E,SUMMARY!$C25) -> 0 | M25: =COUNTIFS('MASTER DSE OCT Inn'!$AA:$AA,M$13,'MASTER DSE OCT Inn'!$E:$E,SUMMARY!$C25) -> 0 | N25: =COUNTIFS('MASTER DSE OCT Inn'!$AA:$AA,N$13,'MASTER DSE OCT Inn'!$E:$E,SUMMARY!$C25) -> 0
... A52: WEST JAKARTA | B52: MC-KEMBANGAN | C52: PT-KEMBANGAN | D52: =COUNTIFS('MASTER DSE OCT Inn'!E:E,SUMMARY!C52) -> 7 | F52: =COUNTIFS('MASTER DSE OCT Inn'!$Z:$Z,F$13,'MASTER DSE OCT Inn'!$E:$E,SUMMARY!$C52) -> 7 | G52: =COUNTIFS('MASTER DSE OCT Inn'!$Z:$Z,G$13,'MASTER DSE OCT Inn'!$E:$E,SUMMARY!$C52) -> 0 | H52: =COUNTIFS('MASTER DSE OCT Inn'!$Z:$Z,H$13,'MASTER DSE OCT Inn'!$E:$E,SUMMARY!$C52) -> 0 | I52: =COUNTIFS('MASTER DSE OCT Inn'!$Z:$Z,I$13,'MASTER DSE OCT Inn'!$E:$E,SUMMARY!$C52) -> 0 | K52: =COUNTIFS('MASTER DSE OCT Inn'!$AA:$AA,K$13,'MASTER DSE OCT Inn'!$E:$E,SUMMARY!$C52) -> 7 | L52: =COUNTIFS('MASTER DSE OCT Inn'!$AA:$AA,L$13,'MASTER DSE OCT Inn'!$E:$E,SUMMARY!$C52) -> 0 | M52: =COUNTIFS('MASTER DSE OCT Inn'!$AA:$AA,M$13,'MASTER DSE OCT Inn'!$E:$E,SUMMARY!$C52) -> 0 | N52: =COUNTIFS('MASTER DSE OCT Inn'!$AA:$AA,N$13,'MASTER DSE OCT Inn'!$E:$E,SUMMARY!$C52) -> 0

Sheet MASTER DSE BSM HOA
A4: REGION | B4: BRANCH/AREA | C4: NAMA HOA | D4: MICRO CLUSTER | E4: NAMA DSO | F4: NAMA DSE | G4: ID Telegram | H4: ALAMAT | I4: NO KTP | J4: JENIS KELAMIN | K4: ROLE (SPV/CSO) | L4: MSISDN (YG DIDAFTARKAN MOBO) | M4: EMAIL | N4: REMARKS | O4: RAYON | P4: DSE ID IM3 | Q4: DSE ID 3ID | R4: PT_DSEIDIM3 | S4: PT_DSE3ID | T4: ID Telegram
A5: INNER JAKARTA | B5: BEKASI | C5: Ali Sabana | D5: MC-BEKASI TENGAH | E5: ADITYA HASANUDDIN | F5: DODI SETIONO | H5: perumahan puri lestari gang seroja 11 blok f32/07 sukajaya | I5: 3275050312790011 | J5: PRIA | L5: 628567620678 | O5: BKS_BU_13 | P5: CSOBKST-01 | Q5: CSOBKST-013ID | R5: PT-BEKASI TENGAHCSOBKST-01 | S5: PT-BEKASI TENGAHCSOBKST-013ID | T5: 6613490972
A6: INNER JAKARTA | B6: BEKASI | C6: Ali Sabana | D6: MC-BEKASI TENGAH | E6: ADITYA HASANUDDIN | F6: RESTU SAMBUDI | H6: jalan ujunga harapan gg sejahtera rt002/017 kel bahagia kec babelan depan gg sejahtera 2 | I6: 3216020401940014 | J6: PRIA | L6: 6280086422485 | O6: BKS_BU_17 | P6: CSOBKST-02 | Q6: CSOBKST-023ID | R6: PT-BEKASI TENGAHCSOBKST-02 | S6: PT-BEKASI TENGAHCSOBKST-023ID | T6: 1986015049
A7: INNER JAKARTA | B7: BEKASI | C7: Ali Sabana | D7: MC-BEKASI TENGAH | E7: ADITYA HASANUDDIN | F7: TRI ADI PRASETYO | H7: Jl. Cempaka 9 Bs.11 No. 16 Rt.007/013 Jatisampurna Bekasi | I7: 3275100503920011 | J7: PRIA | K7: CSO | L7: 6280086422482 | M7: adhyprasetyo0031@gmail.com | O7: BKS_BU_21 | P7: CSOBKST-08 | Q7: CSOBKST-083ID | R7: PT-BEKASI TENGAHCSOBKST-08 | S7: PT-BEKASI TENGAHCSOBKST-083ID | T7: 8548433055
A8: INNER JAKARTA | B8: BEKASI | C8: Ali Sabana | D8: MC-BEKASI TENGAH | E8: ADITYA HASANUDDIN | F8: ACHMAD RIZKI FAUZI | G8: 8859636861 | H8: 0 | I8: 3275030101890050 | J8: PRIA | K8: CSO | L8: 6289602778059 | O8: BKS_BU_15 | P8: DSEIN003 | Q8: 1-28825212068 | R8: PT-BEKASI TENGAHDSEIN003 | S8: PT-BEKASI TENGAH1-28825212068 | T8: 8859636861
A9: INNER JAKARTA | B9: BEKASI | C9: Ali Sabana | D9: MC-BEKASI TENGAH | E9: ADITYA HASANUDDIN | F9: AKMAL MAULANA | G9: 6436712136 | H9: kp.pulo timaha rt 011/007 desa Babelan Kota kabupaten Bekasi | I9: 3216021507950014 | J9: PRIA | L9: 6289602778055 | O9: BKS_BU_14 | P9: DSEIN006 | Q9: 1-28825212060 | R9: PT-BEKASI TENGAHDSEIN006 | S9: PT-BEKASI TENGAH1-28825212060 | T9: 6436712136
A10: INNER JAKARTA | B10: BEKASI | C10: Ali Sabana | D10: MC-BEKASI TENGAH | E10: ADITYA HASANUDDIN | F10: AHMAD FIRDAUS | G10: 5102856680 | H10: Taman Cikunir indah blok D no 6 RT 10 RW 11 Bekasi Selatan | I10: 3275042905890016 | J10: PRIA | K10: CSO | L10: 628985561822 | M10: ahmadfirdaus299@gmail.com | O10: BKS_BS_1 | P10: DSEIN007 | Q10: 1-135606436407 | R10: PT-BEKASI TENGAHDSEIN007 | S10: PT-BEKASI TENGAH1-135606436407 | T10: 5102856680
A11: INNER JAKARTA | B11: BEKASI | C11: Ali Sabana | D11: MC-BEKASI TENGAH | E11: ADITYA HASANUDDIN | F11: INDRA PURWANTO | G11: 8082066485 | H11: jl.musholla daarul ibtida no.109 rt01 rw 01 kel.bantar gebang kec.bantar gebang kota bekasi | I11: 3175071003880020 | J11: PRIA | L11: 6289602778072 | O11: BKS_BS_3 | P11: DSEIN019 | Q11: 1-28825212086 | R11: PT-BEKASI TENGAHDSEIN019 | S11: PT-BEKASI TENGAH1-28825212086 | T11: 8082066485
A12: INNER JAKARTA | B12: BEKASI | C12: Ali Sabana | D12: MC-BEKASI TENGAH | E12: ADITYA HASANUDDIN | F12: IRAMA HAREFA | G12: 876793650 | H12: KP Irian No 23 Kecamatan Bekasi Utara | I12: 3275032801030018 | J12: PRIA | K12: CSO | L12: 628985560095 | M12: aldiansa2801@gmail.com | O12: BKS_BU_16 | P12: DSEIN020 | Q12: 1-136179672105 | R12: PT-BEKASI TENGAHDSEIN020 | S12: PT-BEKASI TENGAH1-136179672105 | T12: 876793650
A13: INNER JAKARTA | B13: BEKASI | C13: Ali Sabana | D13: MC-BEKASI TENGAH | E13: ADITYA HASANUDDIN | F13: MUHAMMAD ALDIANSA PANGESTU | G13: 1420948858 | H13: Jl. Letnan Arsyad 2 No. 81 RT/RW 006/012 Kel. Kayuringin Jaya - Bekasi Selatan | I13: 1204041805940004 | J13: PRIA | K13: CSO | L13: 628985561832 | M13: iharefa94@gmail.com | O13: BKS_BS_9 | P13: DSEIN027 | Q13: 1-135596391663 | R13: PT-BEKASI TENGAHDSEIN027 | S13: PT-BEKASI TENGAH1-135596391663 | T13: 1420948858
A14: INNER JAKARTA | B14: BEKASI | C14: Ali Sabana | D14: MC-BEKASI TENGAH | E14: ADITYA HASANUDDIN | F14: SYAIFUL JAMAL | H14: perum SATRIA INDAH RESIDENT 2 BLOK I NO 35 KELURAHAN SETIA MEKAR TAMBUN UTARA KAB.BEKASI. | I14: 3327111612890004 | J14: PRIA | K14: CSO | L14: 6289607902966 | O14: BKS_BS_2 | P14: DSEIN038 | Q14: 1-170588695616 | R14: PT-BEKASI TENGAHDSEIN038 | S14: PT-BEKASI TENGAH1-170588695616
A15: INNER JAKARTA | B15: BEKASI | C15: Ali Sabana | D15: MC-BEKASI UTARA | E15: RAHAYU UTAMININGSIH | F15: AAN KOSSUNJAMINARA | H15: Kp Rawa Bambu Rt 003/16 Kel Harapan Jaya Kec Bekasi Utara No.0 Rtrw.0 Kel.- Kec.- | I15: 3275032209740019 | J15: PRIA | K15: CSO | L15: 6280086422487 | M15: ankoss2209@gmail.com | O15: BKS_BU_18 | P15: CSOBKST-06 | Q15: CSOBKST-063ID | R15: PT-BEKASI UTARACSOBKST-06 | S15: PT-BEKASI UTARACSOBKST-063ID | T15: 8855252608
A16: INNER JAKARTA | B16: BEKASI | C16: Ali Sabana | D16: MC-BEKASI UTARA | E16: RAHAYU UTAMININGSIH | F16: MOHAMMAD SLAMET | H16: Desa Karanganyar Rt. 001/005 Kel Karanganyar Kec Pagerbarang No.0 Rtrw.0 Kel.- Kec.- | I16: 3328051710820006 | J16: PRIA | K16: CSO | L16: 6280086422488 | M16: slametmuhamad927@gmail.com | O16: BKS_BU_23 | P16: CSOBKST-09 | Q16: CSOBKST-093ID | R16: PT-BEKASI UTARACSOBKST-09 | S16: PT-BEKASI UTARACSOBKST-093ID | T16: 8627734137
A17: INNER JAKARTA | B17: BEKASI | C17: Ali Sabana | D17: MC-BEKASI UTARA | E17: RAHAYU UTAMININGSIH | F17: MUHAMMAD DEDI SAPUTRA | H17: Rawa Silam 1 Rt. 008/006 Kel. Kaliabang Tengah Kec Bekasi Utara No.0 Rtrw.0 Kel.- Kec.- | I17: 3275032505940032 | J17: PRIA | K17: CSO | L17: 6280086422483 | M17: dedysahputra45@gmail.com | O17: BKS_BU_24 | P17: CSOBKST-10 | Q17: CSOBKST-103ID | R17: PT-BEKASI UTARACSOBKST-10 | S17: PT-BEKASI UTARACSOBKST-103ID | T17: 6414405497
A18: INNER JAKARTA | B18: BEKASI | C18: Ali Sabana | D18: MC-BEKASI UTARA | E18: RAHAYU UTAMININGSIH | F18: PARMAN | G18: 6522187953 | H18: jl kh muchtar thabrani rt04/02 no61 margamulya bekasi utara | I18: 3215061012880005 | J18: PRIA | L18: 6289602778054 | O18: BKS_BU_22 | P18: DSEIN030 | Q18: 1-28825212058 | R18: PT-BEKASI UTARADSEIN030 | S18: PT-BEKASI UTARA1-28825212058 | T18: 6522187953
A19: INNER JAKARTA | B19: BEKASI | C19: Ali Sabana | D19: MC-BEKASI UTARA | E19: RAHAYU UTAMININGSIH | F19: YOSEP MARTIN | G19: 8627850949 | H19: villa gading harapan3 jl.elang1 blok E1 no.03 | I19: 3518081405940002 | J19: PRIA | L19: 6289602778053 | O19: BKS_BU_19 | P19: DSEIN040 | Q19: 1-28825212056 | R19: PT-BEKASI UTARADSEIN040 | S19: PT-BEKASI UTARA1-28825212056 | T19: 8627850949
A20: INNER JAKARTA | B20: BEKASI | C20: Ali Sabana | D20: MC-BEKASI UTARA | E20: RAHAYU UTAMININGSIH | F20: MUHAMMAD IQBAL | G20: 1693640001 | H20: kp rawa kalong rt 004 rw 003 tambun utara | I20: 3275020503900012 | J20: PRIA | K20: CSO | L20: 0 | O20: BKS_BU_20 | P20: DSEIN041 | Q20: 1-135596392079 | R20: PT-BEKASI UTARADSEIN041 | S20: PT-BEKASI UTARA1-135596392079 | T20: 1693640001
A21: INNER JAKARTA | B21: BEKASI | C21: Ali Sabana | D21: MC-MUSTIKA JAYA | E21: MUHAMAD RIFALDI | F21: ALFIAN FARDIANSYAH | G21: 6484161430 | H21: kp.cikunir rt 005/ rw 001 jakamulya Bekasi Selatan | I21: 3201131912890003 | J21: PRIA | K21: CSO | L21: 62857177749007 | M21: alfian.fardiansyah89@gmail.com | O21: BKS_BS_10 | P21: CSOBKSB-02 | Q21: CSOBKSB-023ID | R21: PT-MUSTIKA JAYACSOBKSB-02 | S21: PT-MUSTIKA JAYACSOBKSB-023ID | T21: 6484161430
A22: INNER JAKARTA | B22: BEKASI | C22: Ali Sabana | D22: MC-MUSTIKA JAYA | E22: MUHAMAD RIFALDI | F22: MUKTIARTO | H22: jl setia 4 no 43 RT 006/012 Jatiwaringin pondok gede | I22: 3275081602940025 | J22: PRIA | L22: 6280086422484 | O22: BKS_BS_12 | P22: CSOBKSS-04 | Q22: CSOBKSS-043ID | R22: PT-MUSTIKA JAYACSOBKSS-04 | S22: PT-MUSTIKA JAYACSOBKSS-043ID | T22: 6130103877
A23: INNER JAKARTA | B23: BEKASI | C23: Ali Sabana | D23: MC-MUSTIKA JAYA | E23: MUHAMAD RIFALDI | F23: TOFIK HIDAYAT | G23: 6867103460 | H23: Jl Sejahtera Rt 004 Rw 003 Kel Jatiwaringin Kec Pondokgede No.0 Rtrw.0 Kel.- Kec.- | I23: 3275082608810007 | J23: PRIA | K23: CSO | L23: 62857111777787 | M23: topiko78@gmail.com | O23: BKS_BS_11 | P23: CSOBKSS-05 | Q23: CSOBKSS-053ID | R23: PT-MUSTIKA JAYACSOBKSS-05 | S23: PT-MUSTIKA JAYACSOBKSS-053ID | T23: 6867103460
A24: INNER JAKARTA | B24: BEKASI | C24: Ali Sabana | D24: MC-MUSTIKA JAYA | E24: MUHAMAD RIFALDI | F24: TOMMY SAIFUL ATNAN | H24: Kel Makasar No 7 Rt 006 Rw 002 Kel Makasar Kec Makasar No.0 Rtrw.0 Kel.- Kec.- | I24: 3175081507900004 | J24: PRIA | K24: CSO | L24: 62857111166697 | M24: tommy.gembul16@gmail.com | O24: BKS_BS_5 | P24: CSOBKSS-12 | Q24: CSOBKSS-123ID | R24: PT-MUSTIKA JAYACSOBKSS-12 | S24: PT-MUSTIKA JAYACSOBKSS-123ID | T24: 8863650921
A25: INNER JAKARTA | B25: BEKASI | C25: Ali Sabana | D25: MC-MUSTIKA JAYA | E25: MUHAMAD RIFALDI | F25: SYAIPUL BAHRI | H25: Kp. Kebantenan Rt. 002/012 Kel Jatiasih Kec Jatiasih No.0 Rtrw.0 Kel.- Kec.- | I25: 3275091111900034 | J25: PRIA | K25: CSO | L25: 6285770070006 | M25: syaipulabian163@gmail.com | O25: BKS_BS_8 | P25: CSOBKST-11 | Q25: CSOBKST-113ID | R25: PT-MUSTIKA JAYACSOBKST-11 | S25: PT-MUSTIKA JAYACSOBKST-113ID | T25: 7552356704
A26: INNER JAKARTA | B26: BEKASI | C26: Ali Sabana | D26: MC-MUSTIKA JAYA | E26: MUHAMAD RIFALDI | F26: ACHMAD ABDULAH | G26: 8976538478 | H26: kp Cakung RT 02 RW 012 Kelurahan jatimekar kecamatan Jatiasih kota bekasi | I26: 3275092707870010 | J26: PRIA | L26: 6289602778073 | O26: BKS_BS_6 | P26: DSEIN002 | Q26: 1-28825212088 | R26: PT-MUSTIKA JAYADSEIN002 | S26: PT-MUSTIKA JAYA1-28825212088 | T26: 8976538478
A27: INNER JAKARTA | B27: BEKASI | C27: Ali Sabana | D27: MC-MUSTIKA JAYA | E27: MUHAMAD RIFALDI | F27: HERRY CHRISTIAN | H27: Kp.kebantenan gg.anugerah rt.05 rw.06 no.65 | I27: 3275091902840012 | J27: PRIA | K27: CSO | L27: 628985560042 | M27: herry.christian4@gmail.com | O27: BKS_BS_7 | P27: DSEIN018 | Q27: 1-136173742121 | R27: PT-MUSTIKA JAYADSEIN018 | S27: PT-MUSTIKA JAYA1-136173742121
A28: INNER JAKARTA | B28: BEKASI | C28: Ali Sabana | D28: MC-MUSTIKA JAYA | E28: MUHAMAD RIFALDI | F28: MUHAMMAD ZULFIKAR | G28: 5258172895 | H28: jl mushola arifiah RT 008/007 | I28: 3275082707960021 | J28: PRIA | L28: 6289602778079 | O28: BKS_BS_4 | P28: DSEIN028 | Q28: 1-28825212100 | R28: PT-MUSTIKA JAYADSEIN028 | S28: PT-MUSTIKA JAYA1-28825212100 | T28: 5258172895
A29: INNER JAKARTA | B29: BEKASI | C29: Ali Sabana | D29: MC-PONDOK GEDE | E29: RULLI PRATAMA | F29: NURHAEDI | G29: 6459739401 | H29: Jl. Kp. Cikunir, RT/RW.002/008, No.29, Kel. Jatikramat, Kec. Jatiasih 17421 | I29: 3201170809850002 | J29: PRIA | L29: 628166333327 | O29: BKS_PG_26 | P29: CSOBKSB-04 | Q29: CSOBKSB-043ID | R29: PT-PONDOK GEDECSOBKSB-04 | S29: PT-PONDOK GEDECSOBKSB-043ID | T29: 6459739401
A30: INNER JAKARTA | B30: BEKASI | C30: Ali Sabana | D30: MC-PONDOK GEDE | E30: RULLI PRATAMA | F30: SUSANTO | G30: 7906117504 | H30: jl. pisang kepok lll FD3 NO.2 RT.002/RW.012 KEL.KOTA BARU KEC.BEKASI BARAT KOTA BEKASI | I30: 3275081611870017 | J30: PRIA | L30: 628165671777 | O30: BKS_PG_32 | P30: CSOBKSB-08 | Q30: CSOBKSB-083ID | R30: PT-PONDOK GEDECSOBKSB-08 | S30: PT-PONDOK GEDECSOBKSB-083ID | T30: 7906117504
A31: INNER JAKARTA | B31: BEKASI | C31: Ali Sabana | D31: MC-PONDOK GEDE | E31: RULLI PRATAMA | F31: HERMANSYAH | G31: 6478070708 | H31: Jl. H. Ahyar, RW.5, Duren Sawit, Kec. Duren Sawit, Kota Jakarta Timur, Daerah Khusus Ibukota Jakarta 13440, Indonesia | I31: 3175071504820010 | J31: PRIA | L31: 62858940940827 | O31: BKS_PG_27 | P31: CSOBKSB-09 | Q31: CSOBKSB-093ID | R31: PT-PONDOK GEDECSOBKSB-09 | S31: PT-PONDOK GEDECSOBKSB-093ID | T31: 6478070708
A32: INNER JAKARTA | B32: BEKASI | C32: Ali Sabana | D32: MC-PONDOK GEDE | E32: RULLI PRATAMA | F32: MULYADI | G32: 6443249460 | H32: jln. kp sumur klender rt. 006 rw. 017 no. 02 jakarta timur | I32: 3175072710880014 | J32: PRIA | L32: 62857765555347 | O32: BKS_PG_33 | P32: CSOBKSB-10 | Q32: CSOBKSB-103ID | R32: PT-PONDOK GEDECSOBKSB-10 | S32: PT-PONDOK GEDECSOBKSB-103ID | T32: 6443249460
A33: INNER JAKARTA | B33: BEKASI | C33: Ali Sabana | D33: MC-PONDOK GEDE | E33: RULLI PRATAMA | F33: AGUNG PURWOKO | G33: 6139822823 | H33: jl.kramataris no.128 RT.07 RW 03 Setu ,cipayung | I33: 3175100901780002 | J33: PRIA | L33: 62856970280217 | O33: BKS_PG_31 | P33: CSOBKSB-11 | Q33: CSOBKSB-113ID | R33: PT-PONDOK GEDECSOBKSB-11 | S33: PT-PONDOK GEDECSOBKSB-113ID | T33: 6139822823
A34: INNER JAKARTA | B34: BEKASI | C34: Ali Sabana | D34: MC-PONDOK GEDE | E34: RULLI PRATAMA | F34: MUHAMMAD RIZALDI | G34: 5531128311 | H34: jalan celepuk 1 rt 003 rw012, jatimakmur,pondok gede, bekasi | I34: 3275082107920008 | J34: PRIA | L34: 62815746723287 | O34: BKS_PG_25 | P34: CSOBKSB-16 | Q34: CSOBKSB-163ID | R34: PT-PONDOK GEDECSOBKSB-16 | S34: PT-PONDOK GEDECSOBKSB-163ID | T34: 5531128311
A35: INNER JAKARTA | B35: BEKASI | C35: Ali Sabana | D35: MC-PONDOK GEDE | E35: RULLI PRATAMA | F35: SANDY SAPUTRA | G35: 8830859485 | H35: Kp Pedurenan Rt05 Rw011 Jatiluhur Jatiasih Bekasi kota | I35: 3275022305800020 | J35: PRIA | K35: CSO | L35: 628985560045 | M35: Saputrasandi2305@gamil.com | O35: BKS_PG_30 | P35: DSEIN001 | Q35: 1-136173742147 | R35: PT-PONDOK GEDEDSEIN001 | S35: PT-PONDOK GEDE1-136173742147 | T35: 8830859485
A36: INNER JAKARTA | B36: BEKASI | C36: Ali Sabana | D36: MC-PONDOK GEDE | E36: RULLI PRATAMA | F36: ADNAN S BADRUN | G36: 7626944116 | H36: Taman Cikunir Indah Blok C5 No.10 RT001/ RW011 Jakamulya Bekasi Selatan 17146 | I36: 3275042511870015 | J36: PRIA | L36: 6289602778076 | O36: BKS_PG_28 | P36: DSEIN004 | Q36: 1-28825212094 | R36: PT-PONDOK GEDEDSEIN004 | S36: PT-PONDOK GEDE1-28825212094 | T36: 7626944116
A37: INNER JAKARTA | B37: BEKASI | C37: Ali Sabana | D37: MC-PONDOK GEDE | E37: RULLI PRATAMA | F37: ZULFIKAR | G37: 8677906122 | H37: Jl balai rakyat jakarta timur | I37: 3175073108840007 | J37: PRIA | K37: CSO | L37: 6289602778077 | M37: 1718arzu@gmail.com | O37: BKS_PG_34 | P37: DSEIN022 | Q37: 1-28825212096 | R37: PT-PONDOK GEDEDSEIN022 | S37: PT-PONDOK GEDE1-28825212096 | T37: 8677906122
A38: INNER JAKARTA | B38: BEKASI | C38: Ali Sabana | D38: MC-PONDOK GEDE | E38: RULLI PRATAMA | F38: SAYADI MAHMUD | G38: 8819253454 | H38: puri bukit hijau 16 no 20 rt 03 rw 05 kampung sawah | I38: 3304020606950002 | J38: PRIA | L38: 6289602778078 | O38: BKS_PG_29 | P38: DSEIN037 | Q38: 1-28825212098 | R38: PT-PONDOK GEDEDSEIN037 | S38: PT-PONDOK GEDE1-28825212098 | T38: 8819253454
A39: INNER JAKARTA | B39: CENTRAL NORTH JAKARTA | C39: Ragus Sularto | D39: MC-CEMPAKA PUTIH | E39: SUHENDRA | F39: EKI LIFYANTO | G39: 7318574582 | H39: JALAN SUNTER GEDUNG RUBUH RT.010/RW.002 KOTA JAKARTA UTARA 14360 | I39: 3172022209800012 | J39: PRIA | K39: CSO | L39: 6285771315013 | O39: CNJ_JP_1 | P39: 2613050977 | Q39: 26130509773ID | R39: PT-CEMPAKA PUTIH2613050977 | S39: PT-CEMPAKA PUTIH26130509773ID | T39: 7318574582
A40: INNER JAKARTA | B40: CENTRAL NORTH JAKARTA | C40: Ragus Sularto | D40: MC-CEMPAKA PUTIH | E40: SUHENDRA | F40: SANDRA | G40: 1445450502 | H40: MERUYA UTARA RT 03/ RW 04 | I40: 3173080412921000 | J40: PRIA | K40: CSO | L40: 6281511649202 | O40: CNJ_JP_2 | P40: 2613052398 | Q40: 26130523983ID | R40: PT-CEMPAKA PUTIH2613052398 | S40: PT-CEMPAKA PUTIH26130523983ID | T40: 1445450502
A41: INNER JAKARTA | B41: CENTRAL NORTH JAKARTA | C41: Ragus Sularto | D41: MC-CEMPAKA PUTIH | E41: SUHENDRA | F41: RIYANTO | G41: 6452805492 | H41: JL.SUMUR BATU RT.008/RW.008 KOTA JAKARTA PUSAT 10640 | I41: 3171031901760008 | J41: PRIA | K41: CSO | L41: 62857991691857 | O41: CNJ_JP_6 | P41: CSOBUANAJKP05 | Q41: CSOBUANAJKP053ID | R41: PT-CEMPAKA PUTIHCSOBUANAJKP05 | S41: PT-CEMPAKA PUTIHCSOBUANAJKP053ID | T41: 6452805492
A42: INNER JAKARTA | B42: CENTRAL NORTH JAKARTA | C42: Ragus Sularto | D42: MC-CEMPAKA PUTIH | E42: SUHENDRA | F42: DEDE SULAIMAN | G42: 8101087465 | H42: DUSUN II RT.002/RW.002 KABUPATEN LAMPUNG TENGAH 34158 | I42: 1802260801950002 | J42: PRIA | K42: CSO | L42: 62858606096957 | O42: CNJ_JP_8 | P42: CSOBUANAJKP07 | Q42: CSOBUANAJKP073ID | R42: PT-CEMPAKA PUTIHCSOBUANAJKP07 | S42: PT-CEMPAKA PUTIHCSOBUANAJKP073ID | T42: 8101087465
A43: INNER JAKARTA | B43: CENTRAL NORTH JAKARTA | C43: Ragus Sularto | D43: MC-CEMPAKA PUTIH | E43: SUHENDRA | F43: DJAMALUDIN HARYADI | G43: 7802374707 | H43: KEMAYORAN TENGAH 3 RT.009/RW.007 KOTA JAKARTA PUSAT 10620 | I43: 3171032703880002 | J43: PRIA | K43: CSO | L43: 62857773555597 | O43: CNJ_JP_9 | P43: CSOBUANAJKP08 | Q43: CSOBUANAJKP083ID | R43: PT-CEMPAKA PUTIHCSOBUANAJKP08 | S43: PT-CEMPAKA PUTIHCSOBUANAJKP083ID | T43: 7802374707
...

Sheet dari web teleport
A1: Nama DSE | B1: Kode / Sales ID | C1: Sales Type | D1: Role | E1: Brand | F1: Territory (Cluster) | G1: CSE | H1: Telegram | I1: Status Telegram | J1: Status | K1: Aksi
A2: AAB ABDUL ROSID | B2: 2613050984 | C2: DSE | D2: DSE | E2: IM3 | F2: INNER JAKARTA EAST | G2: RIAN SANJAYA SURNA | H2: 1521678273 | I2: Belum Dicek | J2: ● Aktif | K2: Edit Profil 🔴
A3: AAN KOS | B3: CSOBKST-06 | C3: DSE | D3: DSE | E3: IM3 | F3: INNER JAKARTA EAST | G3: RAHAYU UTAMININGSIH | H3: 8855252608 | I3: Belum Dicek | J3: ● Aktif | K3: Edit Profil 🔴
A4: Aan nalury | B4: DSE0808 | C4: DSE + Store Promotor | D4: DSE | E4: — | F4: — | G4: — | H4: 8172557940 | I4: Belum Dicek | J4: ● Aktif | K4: Edit Profil 🔴
A5: AAN SETIADI | B5: 2613051028 | C5: DSE | D5: DSE | E5: 3ID | F5: INNER JAKARTA WEST | G5: ARIE SETYO PRABOWO | H5: 1648983729 | I5: Belum Dicek | J5: ● Aktif | K5: Edit Profil 🔴
A6: AAR ARDIANSYAH | B6: GSE-KARAWANG2 | C6: GSE | D6: DSE | E6: — | F6: — | G6: — | H6: 7555884957 | I6: Belum Dicek | J6: ● Aktif | K6: Edit Profil 🔴
A7: ABDUL AZIZ KAMIL RAFIKOLAN | B7: USR0037 | C7: Leader CSE/RSE/BSM + Store Promotor | D7: Supervisor | E7: — | F7: — | G7: — | H7: 327648261 | I7: NOT BINDED | J7: ● Aktif | K7: Edit Profil 🔴
A8: ABDUL HAKIM | B8: DSETMUN04 | C8: DSE | D8: DSE | E8: IM3 | F8: INNER JAKARTA EAST | G8: R. SYARIEF DURAHMAN | H8: 8447462899 | I8: Belum Dicek | J8: ● Aktif | K8: Edit Profil 🔴
A9: ABDUL HALIM SOEMARDI | B9: 1-136287627234 | C9: DSE | D9: DSE | E9: 3ID | F9: INNER JAKARTA WEST | G9: INVENT RADIANTI PRATIWI | H9: 7986688443 | I9: Belum Dicek | J9: ● Aktif | K9: Edit Profil 🔴
A10: ABDUL ROHIM | B10: CSO-UTARA-06 | C10: DSE | D10: DSE | E10: IM3 | F10: INNER JAKARTA EAST | G10: AGAM EKANANDA GUMELAR | H10: 7871774207 | I10: Belum Dicek | J10: ● Aktif | K10: Edit Profil 🔴
A11: ABDUL WAHAB IBRAHIM | B11: 458231 | C11: DSF | D11: DSE | E11: 3ID | F11: INNER JAKARTA EAST | G11: MUHAMAD SHANDI MAULIDRIZKI | H11: 6778073837 | I11: Belum Dicek | J11: ● Aktif | K11: Edit Profil 🔴
A12: ACHMAD ABDULAH | B12: 1-28825212088 | C12: DSE | D12: DSE | E12: 3ID | F12: INNER JAKARTA EAST | G12: ADITYA HASANUDDIN | H12: 8976538478 | I12: Belum Dicek | J12: ● Aktif | K12: Edit Profil 🔴
A13: ACHMAD RIZKI FAUZI | B13: 1-28825212068 | C13: DSE | D13: DSE | E13: 3ID | F13: INNER JAKARTA EAST | G13: SEPTIAN AJI PUTRA | H13: 8859636861 | I13: Belum Dicek | J13: ● Aktif | K13: Edit Profil 🔴
A14: ACHMAD SYARIF | B14: DSETMUN07 | C14: DSE | D14: DSE | E14: IM3 | F14: INNER JAKARTA EAST | G14: R. SYARIEF DURAHMAN | H14: 8280479968 | I14: Belum Dicek | J14: ● Aktif | K14: Edit Profil 🔴
A15: Achmat Rizal | B15: DSEDURSAW703 | C15: DSE | D15: DSE | E15: IM3 | F15: INNER JAKARTA WEST | G15: FAHMI KURNIANTO | H15: 1620322999 | I15: Belum Dicek | J15: ● Aktif | K15: Edit Profil 🔴
A16: ADAM GITA WANA | B16: CSO-SELATAN-08 | C16: DSE + DSE Promotor | D16: DSE | E16: IM3 | F16: INNER JAKARTA EAST | G16: THEOVILLUS MARTHIN YOHANES | H16: 8492045610 | I16: NOT BINDED | J16: ● Aktif | K16: Edit Profil 🔴
A17: ADE ELVIANTO | B17: DSETMUN10 | C17: DSE | D17: DSE | E17: IM3 | F17: INNER JAKARTA EAST | G17: R. SYARIEF DURAHMAN | H17: 7128414274 | I17: Belum Dicek | J17: ● Aktif | K17: Edit Profil 🔴
A18: Ade Jafar Shodiq | B18: DSE0574 | C18: Store Promotor | D18: DSE | E18: IM3 | F18: INNER JAKARTA EAST | G18: R. SYARIEF DURAHMAN | H18: 6968874426 | I18: NOT BINDED | J18: ● Aktif | K18: Edit Profil 🔴
A19: Ade muhidin | B19: DSE0768 | C19: DSE | D19: DSE | E19: — | F19: — | G19: — | H19: 8614548434 | I19: Belum Dicek | J19: ● Aktif | K19: Edit Profil 🔴
A20: Ade Novrianto | B20: DSECIPCIR295 | C20: DSE | D20: DSE | E20: IM3 | F20: INNER JAKARTA WEST | G20: ABDUL AZIZ KAMIL RAFIKOLAN | H20: 912960452 | I20: Belum Dicek | J20: ● Aktif | K20: Edit Profil 🔴
A21: ADHITYA PRATAMA | B21: USR0052 | C21: Leader CSE/RSE/BSM | D21: Supervisor | E21: — | F21: — | G21: — | H21: 7107170355 | I21: Belum Dicek | J21: ● Aktif | K21: Edit Profil 🔴
A22: ADIA ERES RUANTINO | B22: 2613050982 | C22: DSE | D22: DSE | E22: IM3 | F22: INNER JAKARTA EAST | G22: RIAN SANJAYA SURNA | H22: 6923528438 | I22: Belum Dicek | J22: ● Aktif | K22: Edit Profil 🔴
A23: ADIAR | B23: 1-135556558807 | C23: DSE | D23: DSE | E23: 3ID | F23: INNER JAKARTA EAST | G23: ADHITYA PRATAMA | H23: 8824817626 | I23: Belum Dicek | J23: ● Aktif | K23: Edit Profil 🔴
A24: Adini Aulia | B24: DSE0729 | C24: Store Promotor | D24: DSE | E24: — | F24: — | G24: — | H24: 1227263689 | I24: Belum Dicek | J24: ● Aktif | K24: Edit Profil 🔴
A25: Adnan S Badrun | B25: 1-28825212094 | C25: DSE | D25: DSE | E25: 3ID | F25: INNER JAKARTA EAST | G25: RULLI PRATAMA | H25: 7626944116 | I25: Belum Dicek | J25: ● Aktif | K25: Edit Profil 🔴
A26: Ady Suhendry | B26: DSECIPCIR514 | C26: DSE | D26: DSE | E26: IM3 | F26: INNER JAKARTA WEST | G26: ABDUL AZIZ KAMIL RAFIKOLAN | H26: 8057780019 | I26: Belum Dicek | J26: ● Aktif | K26: Edit Profil 🔴
A27: Adytia Hasanudin | B27: DSE0666 | C27: Leader CSE/RSE/BSM | D27: Supervisor | E27: — | F27: — | G27: — | H27: 8583574586 | I27: Belum Dicek | J27: ● Aktif | K27: Edit Profil 🔴
A28: AGAM EKANANDA GUMELAR | B28: USR0027 | C28: Leader CSE/RSE/BSM | D28: Supervisor | E28: — | F28: — | G28: — | H28: 930789892 | I28: Belum Dicek | J28: ● Aktif | K28: Edit Profil 🔴
A29: AGIL TIRTANA | B29: 1-28825212122 | C29: DSE | D29: DSE | E29: 3ID | F29: INNER JAKARTA EAST | G29: MUHAMAD SHANDI MAULIDRIZKI | H29: 5999026420 | I29: NOT BINDED | J29: ● Aktif | K29: Edit Profil 🔴
A30: AGUNG NUGROHO | B30: 1-28825212134 | C30: DSE Promotor + DSE | D30: DSE | E30: 3ID | F30: INNER JAKARTA EAST | G30: MUHAMAD SHANDI MAULIDRIZKI | H30: 7551562093 | I30: NOT BINDED | J30: ● Aktif | K30: Edit Profil 🔴
A31: AGUNG PURWOKO | B31: CSOBKSB-11 | C31: DSE | D31: DSE | E31: IM3 | F31: INNER JAKARTA EAST | G31: MUHAMMAD GUFRON | H31: 6139822823 | I31: Belum Dicek | J31: ● Aktif | K31: Edit Profil 🔴
A32: AGUS JUMAEDI | B32: 1-136297797461 | C32: DSE | D32: DSE | E32: 3ID | F32: INNER JAKARTA WEST | G32: MUHAMMAD REZA FAHLEVI | H32: 7332752873 | I32: Belum Dicek | J32: ● Aktif | K32: Edit Profil 🔴
A33: AGUS KURNIA BUDYONO | B33: DSEBUANAJKU10R | C33: DSE | D33: DSE | E33: IM3 | F33: INNER JAKARTA WEST | G33: RUDI HARDANA DARMAWAN | H33: 8478529371 | I33: Belum Dicek | J33: ● Aktif | K33: Edit Profil 🔴
A34: AGUS SURYO NUGROHO | B34: 1-28825212076 | C34: DSE | D34: DSE | E34: 3ID | F34: INNER JAKARTA EAST | G34: ADITYA HASANUDDIN | H34: 8823702943 | I34: Belum Dicek | J34: ● Aktif | K34: Edit Profil 🔴
... A56: ALDI KRISTIAWAN | B56: GSE-KAB BEKASI1 | C56: GSE | D56: DSE | E56: — | F56: — | G56: — | H56: 8460664080 | I56: Belum Dicek | J56: ● Aktif | K56: Edit Profil 🔴
A57: ALDI THAMRIN | B57: 2613051035 | C57: DSE | D57: DSE | E57: 3ID | F57: INNER JAKARTA WEST | G57: ARIE SETYO PRABOWO | H57: 7897818692 | I57: Belum Dicek | J57: ● Aktif | K57: Edit Profil 🔴
A58: Aldika Fayzal Rahaditya | B58: DSE0664 | C58: Leader CSE/RSE/BSM | D58: Supervisor | E58: — | F58: — | G58: — | H58: 6769811218 | I58: Belum Dicek | J58: ● Aktif | K58: Edit Profil 🔴
A59: Aldisya nisrina putri | B59: STPRO-IN-M021 | C59: Store Promotor | D59: DSE | E59: Hybrid | F59: INNER JAKARTA WEST | G59: — | H59: 6044533550 | I59: Belum Dicek | J59: ● Aktif | K59: Edit Profil 🔴
A60: ALEXANDER MANURUNG | B60: 1-28825211826 | C60: DSE | D60: DSE | E60: 3ID | F60: INNER JAKARTA WEST | G60: RIZKY KURNIAWAN | H60: 8855551259 | I60: Belum Dicek | J60: ● Aktif | K60: Edit Profil 🔴
A61: ALFIAN FARDIANSYAH | B61: CSOBKSB-02 | C61: DSE | D61: DSE | E61: IM3 | F61: INNER JAKARTA EAST | G61: MUHAMMAD GUFRON | H61: 6484161430 | I61: Belum Dicek | J61: ● Aktif | K61: Edit Profil 🔴
...

Sheet Sheet4
A1: BRANCH | B1: MICRO CLUSTER | C1: PARTNER TERRITORY | D1: PARTNER ID NEW | E1: PARTNER ID NEW | F1: Propose | G1: Propose | H1: ID RE-CREATE | I1: ID RE-CREATE | J1: STATUS - 261007 | K1: STATUS - 261007 | L1: ID RE-CREATE | M1: ID RE-CREATE | N1: STATUS | O1: STATUS | P1: AGENCY NAME | Q1: MSISDN ada | R1: Login SALESHUB | S1: RESET PIN IM3 | T1: RESET PIN 3ID | U1: PJP IM3 | V1: PJP 3ID | W1: Inject Saldo IM3 | X1: Inject Saldo 3ID | Y1: Sellin SP/VC IM3 | Z1: Sellin SP/VC 3ID | AA1: NOTE | AB1: NAMA DSE | AC1: X | AD1: Re- check Nama DSE | AE1: Status | AF1: NIK AGENCY | AG1: ALAMAT | AH1: NO KTP | AI1: JENIS KELAMIN | AJ1: ROLE (SPV/CSO) | AK1: MSISDN (YG DIDAFTARKAN MOBO) | AL1: MSISDN (YG DIDAFTARKAN MOBO) | AM1: EMAIL | AN1: REMARKS | AO1: RAYON | AP1: Note | AQ1: DATA SOURCE DEMARKASI CIRCLE IDMPC | AR1: DATA SOURCE DEMARKASI CIRCLE NAMAMPC | AS1: DATA SOURCE DEMARKASI CIRCLE IDMP3 | AT1: DATA SOURCE DEMARKASI CIRCLE NAMAMP3 | AU1: cek partner im3 | AV1: cek partner 3id | AW1: DSE ID IM3 | AX1: DSE ID 3ID | AY1: PT_DSEIDIM3 | AZ1: PT_DSE3ID | BA1: cek id dseim3 | BB1: cek iddse 3id | BC1: x | BD1: x | BE1: NOTE
F2: DSE ID Im3 | G2: DSE ID 3ID | H2: IM3 - 261007 | I2: 3ID - 261007 | L2: IM3 | M2: 3ID
A3: BEKASI | B3: MC-BEKASI TENGAH | C3: PT-BEKASI TENGAH | D3: D426102024 | E3: D526102035 | F3: CSOBKST-01 | G3: CSOBKST-013ID | H3: CSOBKST-01 | I3: CSOBKST-013ID | J3: ACTIVE | K3: ACTIVE | P3: STAFFINC | Q3: Tidak Ada | R3: TRUE | S3: TRUE | T3: TRUE | U3: FALSE | V3: FALSE | W3: TRUE | X3: TRUE | Y3: FALSE | Z3: FALSE | AB3: DODI SETIONO | AD3: DODI SETIONO | AE3: DODI SETIONO | AG3: perumahan puri lestari | AH3: 3.2750503e+15 | AI3: PRIA | AL3: 628567620678 | AO3: BKS_BU_13 | AQ3: D426102024 | AR3: SANNIN BROTHER MEGAH, PT | AS3: D526102035 | AT3: PT SANNIN BROTHER MEGAH BEKASI UTARA | AU3: TRUE | AV3: TRUE | AW3: CSOBKST-01 | AX3: CSOBKST-013ID | AY3: PT-BEKASI TENGAHCSOBKST-01 | AZ3: PT-BEKASI TENGAHCSOBKST-013ID | BA3: TRUE | BB3: TRUE | BE3: 0
AG4: gang seroja 11 blok f32/07 sukajaya
A5: BEKASI | B5: MC-BEKASI TENGAH | C5: PT-BEKASI TENGAH | D5: D426102024 | E5: D526102035 | F5: CSOBKST-02 | G5: CSOBKST-023ID | H5: CSOBKST-02 | I5: CSOBKST-023ID | J5: ACTIVE | K5: ACTIVE | P5: STAFFINC | Q5: Tidak Ada | R5: TRUE | S5: TRUE | T5: TRUE | U5: FALSE | V5: FALSE | W5: TRUE | X5: TRUE | Y5: FALSE | Z5: FALSE | AB5: RESTU SAMBUDI | AD5: RESTU SAMBUDI | AE5: RESTU SAMBUDI | AG5: jalan ujunga harapan gg sejahtera rt002/017 kel bahagia kec babelan depan gg sejahtera 2 | AH5: 3.2160204e+15 | AI5: PRIA | AL5: 6280086422485 | AO5: BKS_BU_17 | AQ5: D426102024 | AR5: SANNIN BROTHER MEGAH, PT | AS5: D526102035 | AT5: PT SANNIN BROTHER MEGAH BEKASI UTARA | AU5: TRUE | AV5: TRUE | AW5: CSOBKST-02 | AX5: CSOBKST-023ID | AY5: PT-BEKASI TENGAHCSOBKST-02 | AZ5: PT-BEKASI TENGAHCSOBKST-023ID | BA5: TRUE | BB5: TRUE | BE5: 0
A6: BEKASI | B6: MC-BEKASI TENGAH | C6: PT-BEKASI TENGAH | D6: D426102024 | E6: D526102035 | F6: CSOBKST-08 | G6: CSOBKST-083ID | H6: CSOBKST-08 | I6: CSOBKST-083ID | J6: ACTIVE | K6: ACTIVE | P6: STAFFINC | Q6: Ada | R6: TRUE | S6: TRUE | T6: TRUE | U6: FALSE | V6: FALSE | W6: TRUE | X6: TRUE | Y6: FALSE | Z6: FALSE | AB6: TRI ADI PRASETYO | AD6: TRI ADI PRASETYO | AE6: TRI ADI PRASETYO | AF6: FALSE | AG6: Jl. Cempaka 9 Bs.11 No. 16 Rt.007/013 Jatisampurna Bekasi | AH6: 3.2751005e+15 | AI6: PRIA | AJ6: CSO | AK6: 85591021413 | AL6: 6280086422482 | AM6: adhyprasetyo0031@gmail.com | AO6: BKS_BU_21 | AP6: Nama tidak sesuai | AQ6: D426102024 | AR6: SANNIN BROTHER MEGAH, PT | AS6: D526102035 | AT6: PT SANNIN BROTHER MEGAH BEKASI UTARA | AU6: TRUE | AV6: TRUE | AW6: CSOBKST-08 | AX6: CSOBKST-083ID | AY6: PT-BEKASI TENGAHCSOBKST-08 | AZ6: PT-BEKASI TENGAHCSOBKST-083ID | BA6: TRUE | BB6: TRUE | BE6: 0
A7: BEKASI | B7: MC-BEKASI TENGAH | C7: PT-BEKASI TENGAH | D7: D426102024 | E7: D526102035 | F7: DSEIN003 | G7: 1-28825212068 | H7: DSEIN003 | I7: 1-28825212068 | J7: ACTIVE | K7: ACTIVE | P7: STAFFINC | Q7: Tidak Ada | R7: TRUE | S7: TRUE | T7: TRUE | U7: FALSE | V7: FALSE | W7: TRUE | X7: TRUE | Y7: FALSE | Z7: FALSE | AB7: ACHMAD RIZKI FAUZI | AD7: ACHMAD RIZKI FAUZI | AE7: ACHMAD RIZKI FAUZI | AG7: 0 | AH7: 3.2750301e+15 | AI7: PRIA | AJ7: CSO | AL7: 6289602778059 | AO7: BKS_BU_15 | AQ7: D426102024 | AR7: SANNIN BROTHER MEGAH, PT | AS7: D526102035 | AT7: PT SANNIN BROTHER MEGAH BEKASI UTARA | AU7: TRUE | AV7: TRUE | AW7: DSEIN003 | AX7: 1-28825212068 | AY7: PT-BEKASI TENGAHDSEIN003 | AZ7: PT-BEKASI TENGAH1-28825212068 | BA7: TRUE | BB7: TRUE | BE7: 0
A8: BEKASI | B8: MC-BEKASI TENGAH | C8: PT-BEKASI TENGAH | D8: D426102024 | E8: D526102035 | F8: DSEIN006 | G8: 1-28825212060 | H8: DSEIN006 | I8: 1-28825212060 | J8: ACTIVE | K8: ACTIVE | P8: STAFFINC | Q8: Tidak Ada | R8: TRUE | S8: TRUE | T8: TRUE | U8: FALSE | V8: FALSE | W8: TRUE | X8: TRUE | Y8: FALSE | Z8: FALSE | AB8: AKMAL MAULANA | AD8: AKMAL MAULANA | AE8: AKMAL MAULANA | AG8: kp.pulo timaha rt 011/007 desa Babelan Kota kabupaten Bekasi | AH8: 3.2160215e+15 | AI8: PRIA | AL8: 6289602778055 | AO8: BKS_BU_14 | AQ8: D426102024 | AR8: SANNIN BROTHER MEGAH, PT | AS8: D526102035 | AT8: PT SANNIN BROTHER MEGAH BEKASI UTARA | AU8: TRUE | AV8: TRUE | AW8: DSEIN006 | AX8: 1-28825212060 | AY8: PT-BEKASI TENGAHDSEIN006 | AZ8: PT-BEKASI TENGAH1-28825212060 | BA8: TRUE | BB8: TRUE | BE8: 0
A9: BEKASI | B9: MC-BEKASI TENGAH | C9: PT-BEKASI TENGAH | D9: D426102024 | E9: D526102035 | F9: DSEIN007 | G9: 1-135606436407 | H9: DSEIN007 | I9: 1-135606436407 | J9: ACTIVE | K9: ACTIVE | P9: STAFFINC | Q9: Ada | R9: TRUE | S9: TRUE | T9: TRUE | U9: FALSE | V9: FALSE | W9: TRUE | X9: TRUE | Y9: FALSE | Z9: FALSE | AB9: AHMAD FIRDAUS | AD9: ASEP RAHMAN MULYANA (DSE Resign Bln Feb) | AE9: AHMAD FIRDAUS | AF9: FALSE | AG9: Taman Cikunir indah blok D no 6 RT 10 RW 11 Bekasi Selatan | AH9: 3.2750429e+15 | AI9: PRIA | AJ9: CSO | AK9: 8985561822 | AL9: 628985561822 | AM9: ahmadfirdaus299@gmail.com | AO9: BKS_BS_1 | AP9: Nama tidak sesuai | AQ9: D426102024 | AR9: SANNIN BROTHER MEGAH, PT | AS9: D526102035 | AT9: PT SANNIN BROTHER MEGAH BEKASI UTARA | AU9: TRUE | AV9: TRUE | AW9: DSEIN007 | AX9: 1-135606436407 | AY9: PT-BEKASI TENGAHDSEIN007 | AZ9: PT-BEKASI TENGAH1-135606436407 | BA9: TRUE | BB9: TRUE | BE9: 0
A10: BEKASI | B10: MC-BEKASI TENGAH | C10: PT-BEKASI TENGAH | D10: D426102024 | E10: D526102035 | F10: DSEIN019 | G10: 1-28825212086 | H10: DSEIN019 | I10: 1-28825212086 | J10: ACTIVE | K10: ACTIVE | P10: STAFFINC | Q10: Tidak Ada | R10: TRUE | S10: TRUE | T10: TRUE | U10: FALSE | V10: FALSE | W10: TRUE | X10: TRUE | Y10: FALSE | Z10: FALSE | AB10: INDRA PURWANTO | AD10: INDRA PURWANTO | AE10: INDRA PURWANTO | AG10: jl.musholla daarul ibtida no.109 rt01 rw 01 kel.bantar gebang kec.bantar gebang kota bekasi | AH10: 3.175071e+15 | AI10: PRIA | AL10: 6289602778072 | AO10: BKS_BS_3 | AQ10: D426102024 | AR10: SANNIN BROTHER MEGAH, PT | AS10: D526102035 | AT10: PT SANNIN BROTHER MEGAH BEKASI UTARA | AU10: TRUE | AV10: TRUE | AW10: DSEIN019 | AX10: 1-28825212086 | AY10: PT-BEKASI TENGAHDSEIN019 | AZ10: PT-BEKASI TENGAH1-28825212086 | BA10: TRUE | BB10: TRUE | BE10: 0
A11: BEKASI | B11: MC-BEKASI TENGAH | C11: PT-BEKASI TENGAH | D11: D426102024 | E11: D526102035 | F11: DSEIN020 | G11: 1-136179672105 | H11: DSEIN020 | I11: 1-136179672105 | J11: ACTIVE | K11: ACTIVE | P11: STAFFINC | Q11: Ada | R11: TRUE | S11: TRUE | T11: TRUE | U11: FALSE | V11: FALSE | W11: TRUE | X11: TRUE | Y11: FALSE | Z11: FALSE | AB11: IRAMA HAREFA | AD11: IRAMA HAREFA | AE11: MUHAMMAD ALDIANSA PANGESTU | AF11: FALSE | AG11: KP Irian No 23 Kecamatan Bekasi Utara | AH11: 3.2750328e+15 | AI11: PRIA | AJ11: CSO | AK11: 895326103063 | AL11: 628985560095 | AM11: aldiansa2801@gmail.com | AO11: BKS_BU_16 | AP11: Nama tidak sesuai | AQ11: D426102024 | AR11: SANNIN BROTHER MEGAH, PT | AS11: D526102035 | AT11: PT SANNIN BROTHER MEGAH BEKASI UTARA | AU11: TRUE | AV11: TRUE | AW11: DSEIN020 | AX11: 1-136179672105 | AY11: PT-BEKASI TENGAHDSEIN020 | AZ11: PT-BEKASI TENGAH1-136179672105 | BA11: TRUE | BB11: TRUE | BE11: 0
A12: BEKASI | B12: MC-BEKASI TENGAH | C12: PT-BEKASI TENGAH | D12: D426102024 | E12: D526102035 | F12: DSEIN027 | G12: 1-135596391663 | H12: DSEIN027 | I12: 1-135596391663 | J12: ACTIVE | K12: ACTIVE | P12: STAFFINC | Q12: Ada | R12: TRUE | S12: TRUE | T12: TRUE | U12: FALSE | V12: FALSE | W12: TRUE | X12: TRUE | Y12: FALSE | Z12: FALSE | AB12: MUHAMMAD ALDIANSA PANGESTU | AD12: MUHAMMAD ALDIANSA PANGESTU | AE12: IRAMA HAREFA | AF12: FALSE | AG12: Jl. Letnan Arsyad 2 No. 81 RT/RW 006/012 Kel. Kayuringin Jaya - Bekasi Selatan | AH12: 1.2040418e+15 | AI12: PRIA | AJ12: CSO | AK12: 8985561832 | AL12: 628985561832 | AM12: iharefa94@gmail.com | AO12: BKS_BS_9 | AP12: Nama tidak sesuai | AQ12: D426102024 | AR12: SANNIN BROTHER MEGAH, PT | AS12: D526102035 | AT12: PT SANNIN BROTHER MEGAH BEKASI UTARA | AU12: TRUE | AV12: TRUE | AW12: DSEIN027 | AX12: 1-135596391663 | AY12: PT-BEKASI TENGAHDSEIN027 | AZ12: PT-BEKASI TENGAH1-135596391663 | BA12: TRUE | BB12: TRUE | BE12: 0
A13: BEKASI | B13: MC-BEKASI TENGAH | C13: PT-BEKASI TENGAH | D13: D426102024 | E13: D526102035 | F13: DSEIN038 | G13: 1-170588695616 | H13: DSEIN038 | I13: 1-170588695616 | J13: ACTIVE | K13: ACTIVE | P13: STAFFINC | Q13: Tidak Ada | R13: TRUE | S13: TRUE | T13: TRUE | U13: FALSE | V13: FALSE | W13: TRUE | X13: TRUE | Y13: FALSE | Z13: FALSE | AB13: SYAIFUL JAMAL | AD13: SYAIFUL JAMAL | AE13: SYAIFUL JAMAL | AG13: perum SATRIA INDAH RESIDENT 2 BLOK I NO 35 KELURAHAN SETIA MEKAR TAMBUN UTARA KAB.BEKASI. | AH13: 3.3271116e+15 | AI13: PRIA | AJ13: CSO | AL13: 6289607902966 | AO13: BKS_BS_2 | AQ13: D426102024 | AR13: SANNIN BROTHER MEGAH, PT | AS13: D526102035 | AT13: PT SANNIN BROTHER MEGAH BEKASI UTARA | AU13: TRUE | AV13: TRUE | AW13: DSEIN038 | AX13: 1-170588695616 | AY13: PT-BEKASI TENGAHDSEIN038 | AZ13: PT-BEKASI TENGAH1-170588695616 | BA13: TRUE | BB13: TRUE | BE13: 0
A14: BEKASI | B14: MC-BEKASI UTARA | C14: PT-BEKASI UTARA | D14: D42609204 | E14: 1-28824058447 | F14: CSOBKST-06 | G14: CSOBKST-063ID | H14: CSOBKST-06 | I14: CSOBKST-063ID | J14: ACTIVE | K14: ACTIVE | P14: STAFFINC | Q14: Ada | R14: TRUE | S14: TRUE | T14: TRUE | U14: FALSE | V14: FALSE | W14: TRUE | X14: TRUE | Y14: FALSE | Z14: FALSE | AB14: AAN KOSSUNJAMINARA | AD14: AAN KOSSUNJAMINARA | AE14: AAN KOSSUNJAMINARA | AF14: FALSE | AG14: Kp Rawa Bambu Rt 003/16 Kel Harapan Jaya Kec Bekasi Utara No.0 Rtrw.0 Kel.- Kec.- | AH14: 3.2750322e+15 | AI14: PRIA | AJ14: CSO | AK14: 8568810881 | AL14: 6280086422487 | AM14: ankoss2209@gmail.com | AO14: BKS_BU_18 | AP14: Nama tidak sesuai | AQ14: D42609204 | AR14: SANNIN BROTHER MEGAH, PT | AS14: 1-28824058447 | AT14: PT SANNIN BROTHER MEGAH BEKASI UTARA | AU14: TRUE | AV14: TRUE | AW14: CSOBKST-06 | AX14: CSOBKST-063ID | AY14: PT-BEKASI UTARACSOBKST-06 | AZ14: PT-BEKASI UTARACSOBKST-063ID | BA14: TRUE | BB14: TRUE | BE14: 0
A15: BEKASI | B15: MC-BEKASI UTARA | C15: PT-BEKASI UTARA | D15: D42609204 | E15: 1-28824058447 | F15: CSOBKST-09 | G15: CSOBKST-093ID | H15: CSOBKST-09 | I15: CSOBKST-093ID | J15: ACTIVE | K15: ACTIVE | P15: STAFFINC | Q15: Ada | R15: TRUE | S15: TRUE | T15: TRUE | U15: FALSE | V15: FALSE | W15: TRUE | X15: TRUE | Y15: FALSE | Z15: FALSE | AB15: MOHAMMAD SLAMET | AD15: MOHAMMAD SLAMET | AE15: MOHAMMAD SLAMET | AF15: FALSE | AG15: Desa Karanganyar Rt. 001/005 Kel Karanganyar Kec Pagerbarang No.0 Rtrw.0 Kel.- Kec.- | AH15: 3.3280517e+15 | AI15: PRIA | AJ15: CSO | AK15: 85717040506 | AL15: 6280086422488 | AM15: slametmuhamad927@gmail.com | AO15: BKS_BU_23 | AP15: Nama tidak sesuai | AQ15: D42609204 | AR15: SANNIN BROTHER MEGAH, PT | AS15: 1-28824058447 | AT15: PT SANNIN BROTHER MEGAH BEKASI UTARA | AU15: TRUE | AV15: TRUE | AW15: CSOBKST-09 | AX15: CSOBKST-093ID | AY15: PT-BEKASI UTARACSOBKST-09 | AZ15: PT-BEKASI UTARACSOBKST-093ID | BA15: TRUE | BB15: TRUE | BE15: 0
A16: BEKASI | B16: MC-BEKASI UTARA | C16: PT-BEKASI UTARA | D16: D42609204 | E16: 1-28824058447 | F16: CSOBKST-10 | G16: CSOBKST-103ID | H16: CSOBKST-10 | I16: CSOBKST-103ID | J16: ACTIVE | K16: ACTIVE | P16: STAFFINC | Q16: Ada | R16: TRUE | S16: TRUE | T16: TRUE | U16: FALSE | V16: FALSE | W16: TRUE | X16: TRUE | Y16: FALSE | Z16: FALSE | AB16: MUHAMMAD DEDI SAPUTRA | AD16: MUHAMMAD DEDI SAPUTRA | AE16: MUHAMMAD DEDI SAPUTRA | AF16: FALSE | AG16: Rawa Silam 1 Rt. 008/006 Kel. Kaliabang Tengah Kec Bekasi Utara No.0 Rtrw.0 Kel.- Kec.- | AH16: 3.2750325e+15 | AI16: PRIA | AJ16: CSO | AK16: 85717185678 | AL16: 6280086422483 | AM16: dedysahputra45@gmail.com | AO16: BKS_BU_24 | AP16: Nama tidak sesuai | AQ16: D42609204 | AR16: SANNIN BROTHER MEGAH, PT | AS16: 1-28824058447 | AT16: PT SANNIN BROTHER MEGAH BEKASI UTARA | AU16: TRUE | AV16: TRUE | AW16: CSOBKST-10 | AX16: CSOBKST-103ID | AY16: PT-BEKASI UTARACSOBKST-10 | AZ16: PT-BEKASI UTARACSOBKST-103ID | BA16: TRUE | BB16: TRUE | BE16: 0
A17: BEKASI | B17: MC-BEKASI UTARA | C17: PT-BEKASI UTARA | D17: D42609204 | E17: 1-28824058447 | F17: DSEIN030 | G17: 1-28825212058 | H17: DSEIN030 | I17: 1-28825212058 | J17: ACTIVE | K17: ACTIVE | P17: STAFFINC | Q17: Tidak Ada | R17: TRUE | S17: TRUE | T17: TRUE | U17: FALSE | V17: FALSE | W17: TRUE | X17: TRUE | Y17: FALSE | Z17: FALSE | AB17: PARMAN | AD17: PARMAN | AE17: PARMAN | AG17: jl kh muchtar thabrani rt04/02 no61 margamulya bekasi utara | AH17: 3.215061e+15 | AI17: PRIA | AL17: 6289602778054 | AO17: BKS_BU_22 | AQ17: D42609204 | AR17: SANNIN BROTHER MEGAH, PT | AS17: 1-28824058447 | AT17: PT SANNIN BROTHER MEGAH BEKASI UTARA | AU17: TRUE | AV17: TRUE | AW17: DSEIN030 | AX17: 1-28825212058 | AY17: PT-BEKASI UTARADSEIN030 | AZ17: PT-BEKASI UTARA1-28825212058 | BA17: TRUE | BB17: TRUE | BE17: 0
A18: BEKASI | B18: MC-BEKASI UTARA | C18: PT-BEKASI UTARA | D18: D42609204 | E18: 1-28824058447 | F18: DSEIN040 | G18: 1-28825212056 | H18: DSEIN040 | I18: 1-28825212056 | J18: ACTIVE | K18: ACTIVE | P18: STAFFINC | Q18: Tidak Ada | R18: TRUE | S18: TRUE | T18: TRUE | U18: FALSE | V18: FALSE | W18: TRUE | X18: TRUE | Y18: FALSE | Z18: FALSE | AB18: YOSEP MARTIN | AD18: YOSEP MARTIN | AE18: YOSEP MARTIN | AG18: villa gading harapan3 jl.elang1 blok E1 no.03 | AH18: 3.5180814e+15 | AI18: PRIA | AL18: 6289602778053 | AO18: BKS_BU_19 | AQ18: D42609204 | AR18: SANNIN BROTHER MEGAH, PT | AS18: 1-28824058447 | AT18: PT SANNIN BROTHER MEGAH BEKASI UTARA | AU18: TRUE | AV18: TRUE | AW18: DSEIN040 | AX18: 1-28825212056 | AY18: PT-BEKASI UTARADSEIN040 | AZ18: PT-BEKASI UTARA1-28825212056 | BA18: TRUE | BB18: TRUE | BE18: 0
A19: BEKASI | B19: MC-BEKASI UTARA | C19: PT-BEKASI UTARA | D19: D42609204 | E19: 1-28824058447 | F19: DSEIN041 | G19: 1-135596392079 | H19: DSEIN041 | I19: 1-135596392079 | J19: ACTIVE | K19: ACTIVE | P19: STAFFINC | Q19: Tidak Ada | R19: TRUE | S19: TRUE | T19: TRUE | U19: FALSE | V19: FALSE | W19: TRUE | X19: TRUE | Y19: FALSE | Z19: FALSE | AB19: MUHAMMAD IQBAL | AG19: kp rawa kalong rt 004 rw 003 tambun utara | AH19: 3.2750205e+15 | AI19: PRIA | AJ19: CSO | AL19: 0 | AO19: BKS_BU_20 | AQ19: D42609204 | AR19: SANNIN BROTHER MEGAH, PT | AS19: 1-28824058447 | AT19: PT SANNIN BROTHER MEGAH BEKASI UTARA | AU19: TRUE | AV19: TRUE | AW19: DSEIN041 | AX19: 1-135596392079 | AY19: PT-BEKASI UTARADSEIN041 | AZ19: PT-BEKASI UTARA1-135596392079 | BA19: TRUE | BB19: TRUE | BE19: 0
